Workbook
Name DateRange: OFFSET([1]Progress!$E$4,0,0,1,COUNTIF([1]Progress!$E$4:$L$4,">0"))
Name Importance1: 'QFD First House'!$CI$44:$CI$63
Name Importance2: 'QFD Second House'!$CJ$44:$CJ$63
Name List1_1: 'QFD First House'!$F$44:$F$63
Name List1_10: 'QFD First House'!$AP$44:$AP$63
Name List1_11: 'QFD First House'!$AT$44:$AT$63
Name List1_12: 'QFD First House'!$AX$44:$AX$63
Name List1_13: 'QFD First House'!$BB$44:$BB$63
Name List1_14: 'QFD First House'!$BF$44:$BF$63
Name List1_15: 'QFD First House'!$BJ$44:$BJ$63
Name List1_16: 'QFD First House'!$BN$44:$BN$63
Name List1_17: 'QFD First House'!$BR$44:$BR$63
Name List1_18: 'QFD First House'!$BV$44:$BV$63
Name List1_19: 'QFD First House'!$BZ$44:$BZ$63
Name List1_2: 'QFD First House'!$J$44:$J$63
Name List1_20: 'QFD First House'!$CD$44:$CD$63
Name List1_3: 'QFD First House'!$N$44:$N$63
Name List1_4: 'QFD First House'!$R$44:$T$63
Name List1_5: 'QFD First House'!$V$44:$V$63
Name List1_6: 'QFD First House'!$Z$44:$Z$63
Name List1_7: 'QFD First House'!$AD$44:$AD$63
Name List1_8: 'QFD First House'!$AH$44:$AH$63
Name List1_9: 'QFD First House'!$AL$44:$AL$63
Name List2_1: 'QFD Second House'!$F$44:$F$63
Name List2_10: 'QFD Second House'!$AP$44:$AP$63
Name List2_11: 'QFD Second House'!$AT$44:$AT$63
Name List2_12: 'QFD Second House'!$AX$44:$AX$63
Name List2_13: 'QFD Second House'!$BB$44:$BB$63
Name List2_14: 'QFD Second House'!$BF$44:$BF$63
Name List2_15: 'QFD Second House'!$BJ$44:$BJ$63
Name List2_16: 'QFD Second House'!$BN$44:$BN$63
Name List2_17: 'QFD Second House'!$BR$44:$BR$63
Name List2_18: 'QFD Second House'!$BV$44:$BV$63
Name List2_19: 'QFD Second House'!$BZ$44:$BZ$63
Name List2_2: 'QFD Second House'!$J$44:$J$63
Name List2_20: 'QFD Second House'!$CD$44:$CD$63
Name List2_3: 'QFD Second House'!$N$44:$N$63
Name List2_4: 'QFD Second House'!$R$44:$R$63
Name List2_5: 'QFD Second House'!$V$44:$V$63
Name List2_6: 'QFD Second House'!$Z$44:$Z$63
Name List2_7: 'QFD Second House'!$AD$44:$AD$63
Name List2_8: 'QFD Second House'!$AH$44:$AH$63
Name List2_9: 'QFD Second House'!$AL$44:$AL$63
Name ParamNames: OFFSET([1]Scorecard!$C$18,0,0,COUNTA([1]Scorecard!$C$18:$C$35))
Name ParamRange: OFFSET([1]Progress!$E$4,[1]Progress!$B$25,0,1,COUNTIF([1]Progress!$E$4:$L$4,">0"))
Name ParamSelect: OFFSET([1]Progress!$B$4,[1]Progress!$B$25,0)
Name ProcessIndex: OFFSET([1]Progress!$C$4,[1]Progress!$B$25,0) & " Progress"
Name YAxisTitle: OFFSET([1]Progress!$C$4,[1]Progress!$B$25,0)

Sheet QFD First House
A1: Project Name: | D1: Enter Name Here
C6: First House
CA8: KEY
CC10: Strong Positive Correlation | CP10: +++
CC12: Medium Positive Correlation | CP12: ++
CC14: Weak Positive Correlation | CP14: +
CC16: No Correlation
CC18: Weak Negative Correlation | CP18: -
CC20: Medium Negative Correlation | CP20: - -
CC22: Strong Negative Correlation | CP22: - - -
C27: Interactions
CI34: Customer and Competitive Evaluation
CI41: Importance: 5 High, 1 Low | CK41: Scale: 1 Bad, 5 Good
E42: HOWs - System Objectives
B43: WHATs - Stakeholder Characteristics
F64: {=SUM(IF(List1_1="+++",9*Importance1,IF(List1_1="++",3*Importance1,IF(List1_1="+",1*Importance1,IF(List1_1="-",-1*Importance1,IF(List1_1="- -",-3*Importance1,IF(List1_1="- - -",-9*Importance1,"")))))))} -> 0 | J64: {=SUM(IF(List1_2="+++",9*Importance1,IF(List1_2="++",3*Importance1,IF(List1_2="+",1*Importance1,IF(List1_2="-",-1*Importance1,IF(List1_2="- -",-3*Importance1,IF(List1_2="- - -",-9*Importance2,"")))))))} -> 0 | N64: {=SUM(IF(List1_3="+++",9*Importance1,IF(List1_3="++",3*Importance1,IF(List1_3="+",1*Importance1,IF(List1_3="-",-1*Importance1,IF(List1_3="- -",-3*Importance1,IF(List1_3="- - -",-9*Importance1,"")))))))} -> 0 | R64: {=SUM(IF(List1_4="+++",9*Importance1,IF(List1_4="++",3*Importance1,IF(List1_4="+",1*Importance1,IF(List1_4="-",-1*Importance1,IF(List1_4="- -",-3*Importance1,IF(List1_4="- - -",-9*Importance1,"")))))))} -> 0 | V64: {=SUM(IF(List1_5="+++",9*Importance1,IF(List1_5="++",3*Importance1,IF(List1_5="+",1*Importance1,IF(List1_5="-",-1*Importance1,IF(List1_5="- -",-3*Importance1,IF(List1_5="- - -",-9*Importance1,"")))))))} -> 0 | Z64: {=SUM(IF(List1_6="+++",9*Importance1,IF(List1_6="++",3*Importance1,IF(List1_6="+",1*Importance1,IF(List1_6="-",-1*Importance1,IF(List1_6="- -",-3*Importance1,IF(List1_6="- - -",-9*Importance1,"")))))))} -> 0 | AD64: {=SUM(IF(List1_7="+++",9*Importance1,IF(List1_7="++",3*Importance1,IF(List1_7="+",1*Importance1,IF(List1_7="-",-1*Importance1,IF(List1_7="- -",-3*Importance1,IF(List1_7="- - -",-9*Importance1,"")))))))} -> 0 | AH64: {=SUM(IF(List1_8="+++",9*Importance1,IF(List1_8="++",3*Importance1,IF(List1_8="+",1*Importance1,IF(List1_8="-",-1*Importance1,IF(List1_8="- -",-3*Importance1,IF(List1_8="- - -",-9*Importance1,"")))))))} -> 0 | AL64: {=SUM(IF(List1_9="+++",9*Importance1,IF(List1_9="++",3*Importance1,IF(List1_9="+",1*Importance1,IF(List1_9="-",-1*Importance1,IF(List1_9="- -",-3*Importance1,IF(List1_9="- - -",-9*Importance1,"")))))))} -> 0 | AP64: {=SUM(IF(List1_10="+++",9*Importance1,IF(List1_10="++",3*Importance1,IF(List1_10="+",1*Importance1,IF(List1_10="-",-1*Importance1,IF(List1_10="- -",-3*Importance1,IF(List1_10="- - -",-9*Importance1,"")))))))} -> 0 | AT64: {=SUM(IF(List1_11="+++",9*Importance1,IF(List1_11="++",3*Importance1,IF(List1_11="+",1*Importance1,IF(List1_11="-",-1*Importance1,IF(List1_11="- -",-3*Importance1,IF(List1_11="- - -",-9*Importance1,"")))))))} -> 0 | AX64: {=SUM(IF(List1_12="+++",9*Importance1,IF(List1_12="++",3*Importance1,IF(List1_12="+",1*Importance1,IF(List1_12="-",-1*Importance1,IF(List1_12="- -",-3*Importance1,IF(List1_12="- - -",-9*Importance1,"")))))))} -> 0 | BB64: {=SUM(IF(List1_13="+++",9*Importance1,IF(List1_13="++",3*Importance1,IF(List1_13="+",1*Importance1,IF(List1_13="-",-1*Importance1,IF(List1_13="- -",-3*Importance1,IF(List1_13="- - -",-9*Importance1,"")))))))} -> 0 | BF64: {=SUM(IF(List1_14="+++",9*Importance1,IF(List1_14="++",3*Importance1,IF(List1_14="+",1*Importance1,IF(List1_14="-",-1*Importance1,IF(List1_14="- -",-3*Importance1,IF(List1_14="- - -",-9*Importance1,"")))))))} -> 0 | BJ64: {=SUM(IF(List1_15="+++",9*Importance1,IF(List1_15="++",3*Importance1,IF(List1_15="+",1*Importance1,IF(List1_15="-",-1*Importance1,IF(List1_15="- -",-3*Importance1,IF(List1_15="- - -",-9*Importance1,"")))))))} -> 0 | BN64: {=SUM(IF(List1_16="+++",9*Importance1,IF(List1_16="++",3*Importance1,IF(List1_16="+",1*Importance1,IF(List1_16="-",-1*Importance1,IF(List1_16="- -",-3*Importance1,IF(List1_16="- - -",-9*Importance1,"")))))))} -> 0 | BR64: {=SUM(IF(List1_17="+++",9*Importance1,IF(List1_17="++",3*Importance1,IF(List1_17="+",1*Importance1,IF(List1_17="-",-1*Importance1,IF(List1_17="- -",-3*Importance1,IF(List1_17="- - -",-9*Importance1,"")))))))} -> 0 | BV64: {=SUM(IF(List1_18="+++",9*Importance1,IF(List1_18="++",3*Importance1,IF(List1_18="+",1*Importance1,IF(List1_18="-",-1*Importance1,IF(List1_18="- -",-3*Importance1,IF(List1_18="- - -",-9*Importance1,"")))))))} -> 0 | BZ64: {=SUM(IF(List1_19="+++",9*Importance1,IF(List1_19="++",3*Importance1,IF(List1_19="+",1*Importance1,IF(List1_19="-",-1*Importance1,IF(List1_19="- -",-3*Importance1,IF(List1_19="- - -",-9*Importance1,"")))))))} -> 0 | CD64: {=SUM(IF(List1_20="+++",9*Importance1,IF(List1_20="++",3*Importance1,IF(List1_20="+",1*Importance1,IF(List1_20="-",-1*Importance1,IF(List1_20="- -",-3*Importance1,IF(List1_20="- - -",-9*Importance1,"")))))))} -> 0
C65: Feature Raw Score | F65: =F64 -> 0 | J65: =J64 -> 0 | N65: =N64 -> 0 | R65: =R64 -> 0 | V65: =V64 -> 0 | Z65: =Z64 -> 0 | AD65: =AD64 -> 0 | AH65: =AH64 -> 0 | AL65: =AL64 -> 0 | AP65: =AP64 -> 0 | AT65: =AT64 -> 0 | AX65: =AX64 -> 0 | BB65: =BB64 -> 0 | BF65: =BF64 -> 0 | BJ65: =BJ64 -> 0 | BN65: =BN64 -> 0 | BR65: =BR64 -> 0 | BV65: =BV64 -> 0 | BZ65: =BZ64 -> 0 | CD65: =CD64 -> 0
C66: Feature Rank | F66: =RANK(F65,$F65:$CG65,0) -> 1 | J66: =RANK(J65,$F65:$CG65,0) -> 1 | N66: =RANK(N65,$F65:$CG65,0) -> 1 | R66: =RANK(R65,$F65:$CG65,0) -> 1 | V66: =RANK(V65,$F65:$CG65,0) -> 1 | Z66: =RANK(Z65,$F65:$CG65,0) -> 1 | AD66: =RANK(AD65,$F65:$CG65,0) -> 1 | AH66: =RANK(AH65,$F65:$CG65,0) -> 1 | AL66: =RANK(AL65,$F65:$CG65,0) -> 1 | AP66: =RANK(AP65,$F65:$CG65,0) -> 1 | AT66: =RANK(AT65,$F65:$CG65,0) -> 1 | AX66: =RANK(AX65,$F65:$CG65,0) -> 1 | BB66: =RANK(BB65,$F65:$CG65,0) -> 1 | BF66: =RANK(BF65,$F65:$CG65,0) -> 1 | BJ66: =RANK(BJ65,$F65:$CG65,0) -> 1 | BN66: =RANK(BN65,$F65:$CG65,0) -> 1 | BR66: =RANK(BR65,$F65:$CG65,0) -> 1 | BV66: =RANK(BV65,$F65:$CG65,0) -> 1 | BZ66: =RANK(BZ65,$F65:$CG65,0) -> 1 | CD66: =RANK(CD65,$F65:$CG65,0) -> 1
AG68: Deployment Priorities
C73: Key
B74: 1 | C74: Strong Positive Correlation | E74: +++
B75: 2 | C75: Medium Positive Correlation | E75: ++
B76: 3 | C76: Weak Positive Correlation | E76: +
B77: 4 | C77: No correlation
B78: 5 | C78: Strong Negative Correlation | E78: -
B79: 6 | C79: Medium Negative Correlation | E79: - -
B80: 7 | C80: Weak Negative Correlation | E80: - - -

Sheet QFD Second House
A1: Project Name: | D1: ='QFD First House'!$D$1 -> Enter Name Here
C6: Second House
CA8: KEY
CC10: Strong Positive Correlation | CP10: +++
CC12: Medium Positive Correlation | CP12: ++
CC14: Weak Positive Correlation | CP14: +
CC16: No Correlation
CC18: Weak Negative Correlation | CP18: -
CC20: Medium Negative Correlation | CP20: - -
CC22: Strong Negative Correlation | CP22: - - -
C27: Interactions
CI34: Customer and Competitive Evaluation
CI41: Priority from First House | CJ41: Importance: 5 High, 1 Low | CL41: Scale: 1 Bad, 5 Good
E42: HOWs - Component Specifications
B43: WHATs - System Objectives
B44: =IF('QFD First House'!$F$42 ="","",'QFD First House'!$F$42) | CI44: ='QFD First House'!$F$66:$F$66 -> 1 | CJ44: =IF(CI44<=(MAX(CI$44:CI44)-MIN(CI$44:CI44))*0.2, 5,IF( CI$44<=(MAX(CI$44:CI44)-MIN(CI$44:CI44))*0.4, 4,IF( CI44<=(MAX(CI$44:CI44)-MIN(CI$44:CI44))*0.6, 3,IF(CI44<=(MAX(CI$44:CI44)-MIN(CI$44:CI44))*0.8,2,1)))) -> 1
B45: =IF('QFD First House'!$J$42 ="","",'QFD First House'!$J$42) | CI45: ='QFD First House'!$J$66:$J$66 -> 1 | CJ45: =IF(CI45<=(MAX(CI$44:CI45)-MIN(CI$44:CI45))*0.2, 5,IF( CI$44<=(MAX(CI$44:CI45)-MIN(CI$44:CI45))*0.4, 4,IF( CI45<=(MAX(CI$44:CI45)-MIN(CI$44:CI45))*0.6, 3,IF(CI45<=(MAX(CI$44:CI45)-MIN(CI$44:CI45))*0.8,2,1)))) -> 1
B46: =IF('QFD First House'!$N$42 ="","",'QFD First House'!$N$42) | CI46: ='QFD First House'!$N$66:$N$66 -> 1 | CJ46: =IF(CI46<=(MAX(CI$44:CI46)-MIN(CI$44:CI46))*0.2, 5,IF( CI$44<=(MAX(CI$44:CI46)-MIN(CI$44:CI46))*0.4, 4,IF( CI46<=(MAX(CI$44:CI46)-MIN(CI$44:CI46))*0.6, 3,IF(CI46<=(MAX(CI$44:CI46)-MIN(CI$44:CI46))*0.8,2,1)))) -> 1
B47: =IF('QFD First House'!$R$42 ="","",'QFD First House'!$R$42) | CI47: ='QFD First House'!$R$66:$R$66 -> 1 | CJ47: =IF(CI47<=(MAX(CI$44:CI47)-MIN(CI$44:CI47))*0.2, 5,IF( CI$44<=(MAX(CI$44:CI47)-MIN(CI$44:CI47))*0.4, 4,IF( CI47<=(MAX(CI$44:CI47)-MIN(CI$44:CI47))*0.6, 3,IF(CI47<=(MAX(CI$44:CI47)-MIN(CI$44:CI47))*0.8,2,1)))) -> 1
B48: =IF('QFD First House'!$V$42 ="","",'QFD First House'!$V$42) | CI48: ='QFD First House'!$V$66:$V$66 -> 1 | CJ48: =IF(CI48<=(MAX(CI$44:CI48)-MIN(CI$44:CI48))*0.2, 5,IF( CI$44<=(MAX(CI$44:CI48)-MIN(CI$44:CI48))*0.4, 4,IF( CI48<=(MAX(CI$44:CI48)-MIN(CI$44:CI48))*0.6, 3,IF(CI48<=(MAX(CI$44:CI48)-MIN(CI$44:CI48))*0.8,2,1)))) -> 1
B49: =IF('QFD First House'!$Z$42 ="","",'QFD First House'!$Z$42) | CI49: ='QFD First House'!$Z$66:$Z$66 -> 1 | CJ49: =IF(CI49<=(MAX(CI$44:CI49)-MIN(CI$44:CI49))*0.2, 5,IF( CI$44<=(MAX(CI$44:CI49)-MIN(CI$44:CI49))*0.4, 4,IF( CI49<=(MAX(CI$44:CI49)-MIN(CI$44:CI49))*0.6, 3,IF(CI49<=(MAX(CI$44:CI49)-MIN(CI$44:CI49))*0.8,2,1)))) -> 1
B50: =IF('QFD First House'!$AD$42 ="","",'QFD First House'!$AD$42) | CI50: ='QFD First House'!$AD$66:$AD$66 -> 1 | CJ50: =IF(CI50<=(MAX(CI$44:CI50)-MIN(CI$44:CI50))*0.2, 5,IF( CI$44<=(MAX(CI$44:CI50)-MIN(CI$44:CI50))*0.4, 4,IF( CI50<=(MAX(CI$44:CI50)-MIN(CI$44:CI50))*0.6, 3,IF(CI50<=(MAX(CI$44:CI50)-MIN(CI$44:CI50))*0.8,2,1)))) -> 1
B51: =IF('QFD First House'!$AH$42 ="","",'QFD First House'!$AH$42) | CI51: ='QFD First House'!$AH$66:$AH$66 -> 1 | CJ51: =IF(CI51<=(MAX(CI$44:CI51)-MIN(CI$44:CI51))*0.2, 5,IF( CI$44<=(MAX(CI$44:CI51)-MIN(CI$44:CI51))*0.4, 4,IF( CI51<=(MAX(CI$44:CI51)-MIN(CI$44:CI51))*0.6, 3,IF(CI51<=(MAX(CI$44:CI51)-MIN(CI$44:CI51))*0.8,2,1)))) -> 1
B52: =IF('QFD First House'!$AL$42 ="","",'QFD First House'!$AL$42) | CI52: ='QFD First House'!$AL$66:$AL$66 -> 1 | CJ52: =IF(CI52<=(MAX(CI$44:CI52)-MIN(CI$44:CI52))*0.2, 5,IF( CI$44<=(MAX(CI$44:CI52)-MIN(CI$44:CI52))*0.4, 4,IF( CI52<=(MAX(CI$44:CI52)-MIN(CI$44:CI52))*0.6, 3,IF(CI52<=(MAX(CI$44:CI52)-MIN(CI$44:CI52))*0.8,2,1)))) -> 1
B53: =IF('QFD First House'!$AP$42 ="","",'QFD First House'!$AP$42) | CI53: ='QFD First House'!$AP$66:$AP$66 -> 1 | CJ53: =IF(CI53<=(MAX(CI$44:CI53)-MIN(CI$44:CI53))*0.2, 5,IF( CI$44<=(MAX(CI$44:CI53)-MIN(CI$44:CI53))*0.4, 4,IF( CI53<=(MAX(CI$44:CI53)-MIN(CI$44:CI53))*0.6, 3,IF(CI53<=(MAX(CI$44:CI53)-MIN(CI$44:CI53))*0.8,2,1)))) -> 1
B54: =IF('QFD First House'!$AT$42 ="","",'QFD First House'!$AT$42) | CI54: ='QFD First House'!$AT$66:$AT$66 -> 1 | CJ54: =IF(CI54<=(MAX(CI$44:CI54)-MIN(CI$44:CI54))*0.2, 5,IF( CI$44<=(MAX(CI$44:CI54)-MIN(CI$44:CI54))*0.4, 4,IF( CI54<=(MAX(CI$44:CI54)-MIN(CI$44:CI54))*0.6, 3,IF(CI54<=(MAX(CI$44:CI54)-MIN(CI$44:CI54))*0.8,2,1)))) -> 1
B55: =IF('QFD First House'!$AX$42 ="","",'QFD First House'!$AX$42) | CI55: ='QFD First House'!$AX$66:$AX$66 -> 1 | CJ55: =IF(CI55<=(MAX(CI$44:CI55)-MIN(CI$44:CI55))*0.2, 5,IF( CI$44<=(MAX(CI$44:CI55)-MIN(CI$44:CI55))*0.4, 4,IF( CI55<=(MAX(CI$44:CI55)-MIN(CI$44:CI55))*0.6, 3,IF(CI55<=(MAX(CI$44:CI55)-MIN(CI$44:CI55))*0.8,2,1)))) -> 1
B56: =IF('QFD First House'!$BB$42 ="","",'QFD First House'!$BB$42) | CI56: ='QFD First House'!$BB$66:$BB$66 -> 1 | CJ56: =IF(CI56<=(MAX(CI$44:CI56)-MIN(CI$44:CI56))*0.2, 5,IF( CI$44<=(MAX(CI$44:CI56)-MIN(CI$44:CI56))*0.4, 4,IF( CI56<=(MAX(CI$44:CI56)-MIN(CI$44:CI56))*0.6, 3,IF(CI56<=(MAX(CI$44:CI56)-MIN(CI$44:CI56))*0.8,2,1)))) -> 1
B57: =IF('QFD First House'!$BF$42 ="","",'QFD First House'!$BF$42) | CI57: ='QFD First House'!$BF$66:$BF$66 -> 1 | CJ57: =IF(CI57<=(MAX(CI$44:CI57)-MIN(CI$44:CI57))*0.2, 5,IF( CI$44<=(MAX(CI$44:CI57)-MIN(CI$44:CI57))*0.4, 4,IF( CI57<=(MAX(CI$44:CI57)-MIN(CI$44:CI57))*0.6, 3,IF(CI57<=(MAX(CI$44:CI57)-MIN(CI$44:CI57))*0.8,2,1)))) -> 1
B58: =IF('QFD First House'!$BJ$42 ="","",'QFD First House'!$BJ$42) | CI58: ='QFD First House'!$BJ$66:$BJ$66 -> 1 | CJ58: =IF(CI58<=(MAX(CI$44:CI58)-MIN(CI$44:CI58))*0.2, 5,IF( CI$44<=(MAX(CI$44:CI58)-MIN(CI$44:CI58))*0.4, 4,IF( CI58<=(MAX(CI$44:CI58)-MIN(CI$44:CI58))*0.6, 3,IF(CI58<=(MAX(CI$44:CI58)-MIN(CI$44:CI58))*0.8,2,1)))) -> 1
B59: =IF('QFD First House'!$BN$42 ="","",'QFD First House'!$BN$42) | CI59: ='QFD First House'!$BN$66:$BN$66 -> 1 | CJ59: =IF(CI59<=(MAX(CI$44:CI59)-MIN(CI$44:CI59))*0.2, 5,IF( CI$44<=(MAX(CI$44:CI59)-MIN(CI$44:CI59))*0.4, 4,IF( CI59<=(MAX(CI$44:CI59)-MIN(CI$44:CI59))*0.6, 3,IF(CI59<=(MAX(CI$44:CI59)-MIN(CI$44:CI59))*0.8,2,1)))) -> 1
B60: =IF('QFD First House'!$BR$42 ="","",'QFD First House'!$BR$42) | CI60: ='QFD First House'!$BR$66:$BR$66 -> 1 | CJ60: =IF(CI60<=(MAX(CI$44:CI60)-MIN(CI$44:CI60))*0.2, 5,IF( CI$44<=(MAX(CI$44:CI60)-MIN(CI$44:CI60))*0.4, 4,IF( CI60<=(MAX(CI$44:CI60)-MIN(CI$44:CI60))*0.6, 3,IF(CI60<=(MAX(CI$44:CI60)-MIN(CI$44:CI60))*0.8,2,1)))) -> 1
B61: =IF('QFD First House'!$BV$42 ="","",'QFD First House'!$BV$42) | CI61: ='QFD First House'!$BV$66:$BV$66 -> 1 | CJ61: =IF(CI61<=(MAX(CI$44:CI61)-MIN(CI$44:CI61))*0.2, 5,IF( CI$44<=(MAX(CI$44:CI61)-MIN(CI$44:CI61))*0.4, 4,IF( CI61<=(MAX(CI$44:CI61)-MIN(CI$44:CI61))*0.6, 3,IF(CI61<=(MAX(CI$44:CI61)-MIN(CI$44:CI61))*0.8,2,1)))) -> 1
B62: =IF('QFD First House'!$BZ$42 ="","",'QFD First House'!$BZ$42) | CI62: ='QFD First House'!$BZ$66:$BZ$66 -> 1 | CJ62: =IF(CI62<=(MAX(CI$44:CI62)-MIN(CI$44:CI62))*0.2, 5,IF( CI$44<=(MAX(CI$44:CI62)-MIN(CI$44:CI62))*0.4, 4,IF( CI62<=(MAX(CI$44:CI62)-MIN(CI$44:CI62))*0.6, 3,IF(CI62<=(MAX(CI$44:CI62)-MIN(CI$44:CI62))*0.8,2,1)))) -> 1
B63: =IF('QFD First House'!$CD$42 ="","",'QFD First House'!$CD$42) | CI63: ='QFD First House'!$CD$66:$CD$66 -> 1 | CJ63: =IF(CI63<=(MAX(CI$44:CI63)-MIN(CI$44:CI63))*0.2, 5,IF( CI$44<=(MAX(CI$44:CI63)-MIN(CI$44:CI63))*0.4, 4,IF( CI63<=(MAX(CI$44:CI63)-MIN(CI$44:CI63))*0.6, 3,IF(CI63<=(MAX(CI$44:CI63)-MIN(CI$44:CI63))*0.8,2,1)))) -> 1
F64: {=SUM(IF(List2_1="+++",9*Importance2,IF(List2_1="++",3*Importance2,IF(List2_1="+",1*Importance2,IF(List2_1="-",-1*Importance2,IF(List2_1="- -",-3*Importance2,IF(List2_1="- - -",-9*Importance2,"")))))))} -> 0 | J64: {=SUM(IF(List2_2="+++",9*Importance2,IF(List2_2="++",3*Importance2,IF(List2_2="+",1*Importance2,IF(List2_2="-",-1*Importance2,IF(List2_2="- -",-3*Importance2,IF(List2_2="- - -",-9*Importance2,"")))))))} -> 0 | N64: {=SUM(IF(List2_3="+++",9*Importance2,IF(List2_3="++",3*Importance2,IF(List2_3="+",1*Importance2,IF(List2_3="-",-1*Importance2,IF(List2_3="- -",-3*Importance2,IF(List2_3="- - -",-9*Importance2,"")))))))} -> 0 | R64: {=SUM(IF(List2_4="+++",9*Importance2,IF(List2_4="++",3*Importance2,IF(List2_4="+",1*Importance2,IF(List2_4="-",-1*Importance2,IF(List2_4="- -",-3*Importance2,IF(List2_4="- - -",-9*Importance2,"")))))))} -> 0 | V64: {=SUM(IF(List2_5="+++",9*Importance2,IF(List2_5="++",3*Importance2,IF(List2_5="+",1*Importance2,IF(List2_5="-",-1*Importance2,IF(List2_5="- -",-3*Importance2,IF(List2_5="- - -",-9*Importance2,"")))))))} -> 0 | Z64: {=SUM(IF(List2_6="+++",9*Importance2,IF(List2_6="++",3*Importance2,IF(List2_6="+",1*Importance2,IF(List2_6="-",-1*Importance2,IF(List2_6="- -",-3*Importance2,IF(List2_6="- - -",-9*Importance2,"")))))))} -> 0 | AD64: {=SUM(IF(List2_7="+++",9*Importance2,IF(List2_7="++",3*Importance2,IF(List2_7="+",1*Importance2,IF(List2_7="-",-1*Importance2,IF(List2_7="- -",-3*Importance2,IF(List2_7="- - -",-9*Importance2,"")))))))} -> 0 | AH64: {=SUM(IF(List2_8="+++",9*Importance2,IF(List2_8="++",3*Importance2,IF(List2_8="+",1*Importance2,IF(List2_8="-",-1*Importance2,IF(List2_8="- -",-3*Importance2,IF(List2_8="- - -",-9*Importance2,"")))))))} -> 0 | AL64: {=SUM(IF(List2_9="+++",9*Importance2,IF(List2_9="++",3*Importance2,IF(List2_9="+",1*Importance2,IF(List2_9="-",-1*Importance2,IF(List2_9="- -",-3*Importance2,IF(List2_9="- - -",-9*Importance2,"")))))))} -> 0 | AP64: {=SUM(IF(List2_10="+++",9*Importance2,IF(List2_10="++",3*Importance2,IF(List2_10="+",1*Importance2,IF(List2_10="-",-1*Importance2,IF(List2_10="- -",-3*Importance2,IF(List2_10="- - -",-9*Importance2,"")))))))} -> 0 | AT64: {=SUM(IF(List2_11="+++",9*Importance2,IF(List2_11="++",3*Importance2,IF(List2_11="+",1*Importance2,IF(List2_11="-",-1*Importance2,IF(List2_11="- -",-3*Importance2,IF(List2_11="- - -",-9*Importance2,"")))))))} -> 0 | AX64: {=SUM(IF(List2_12="+++",9*Importance2,IF(List2_12="++",3*Importance2,IF(List2_12="+",1*Importance2,IF(List2_12="-",-1*Importance2,IF(List2_12="- -",-3*Importance2,IF(List2_12="- - -",-9*Importance2,"")))))))} -> 0 | BB64: {=SUM(IF(List2_13="+++",9*Importance2,IF(List2_13="++",3*Importance2,IF(List2_13="+",1*Importance2,IF(List2_13="-",-1*Importance2,IF(List2_13="- -",-3*Importance2,IF(List2_13="- - -",-9*Importance2,"")))))))} -> 0 | BF64: {=SUM(IF(List2_14="+++",9*Importance2,IF(List2_14="++",3*Importance2,IF(List2_14="+",1*Importance2,IF(List2_14="-",-1*Importance2,IF(List2_14="- -",-3*Importance2,IF(List2_14="- - -",-9*Importance2,"")))))))} -> 0 | BJ64: {=SUM(IF(List2_15="+++",9*Importance2,IF(List2_15="++",3*Importance2,IF(List2_15="+",1*Importance2,IF(List2_15="-",-1*Importance2,IF(List2_15="- -",-3*Importance2,IF(List2_15="- - -",-9*Importance2,"")))))))} -> 0 | BN64: {=SUM(IF(List2_16="+++",9*Importance2,IF(List2_16="++",3*Importance2,IF(List2_16="+",1*Importance2,IF(List2_16="-",-1*Importance2,IF(List2_16="- -",-3*Importance2,IF(List2_16="- - -",-9*Importance2,"")))))))} -> 0 | BR64: {=SUM(IF(List2_17="+++",9*Importance2,IF(List2_17="++",3*Importance2,IF(List2_17="+",1*Importance2,IF(List2_17="-",-1*Importance2,IF(List2_17="- -",-3*Importance2,IF(List2_17="- - -",-9*Importance2,"")))))))} -> 0 | BV64: {=SUM(IF(List2_18="+++",9*Importance2,IF(List2_18="++",3*Importance2,IF(List2_18="+",1*Importance2,IF(List2_18="-",-1*Importance2,IF(List2_18="- -",-3*Importance2,IF(List2_18="- - -",-9*Importance2,"")))))))} -> 0 | BZ64: {=SUM(IF(List2_19="+++",9*Importance2,IF(List2_19="++",3*Importance2,IF(List2_19="+",1*Importance2,IF(List2_19="-",-1*Importance2,IF(List2_19="- -",-3*Importance2,IF(List2_19="- - -",-9*Importance2,"")))))))} -> 0 | CD64: {=SUM(IF(List2_20="+++",9*Importance2,IF(List2_20="++",3*Importance2,IF(List2_20="+",1*Importance2,IF(List2_20="-",-1*Importance2,IF(List2_20="- -",-3*Importance2,IF(List2_20="- - -",-9*Importance2,"")))))))} -> 0
C65: Feature Raw Score | F65: =F64 -> 0 | J65: =J64 -> 0 | N65: =N64 -> 0 | R65: =R64 -> 0 | V65: =V64 -> 0 | Z65: =Z64 -> 0 | AD65: =AD64 -> 0 | AH65: =AH64 -> 0 | AL65: =AL64 -> 0 | AP65: =AP64 -> 0 | AT65: =AT64 -> 0 | AX65: =AX64 -> 0 | BB65: =BB64 -> 0 | BF65: =BF64 -> 0 | BJ65: =BJ64 -> 0 | BN65: =BN64 -> 0 | BR65: =BR64 -> 0 | BV65: =BV64 -> 0 | BZ65: =BZ64 -> 0 | CD65: =CD64 -> 0
C66: Feature Rank | F66: =RANK(F65,$F65:$CG65,0) -> 1 | J66: =RANK(J65,$F65:$CG65,0) -> 1 | N66: =RANK(N65,$F65:$CG65,0) -> 1 | R66: =RANK(R65,$F65:$CG65,0) -> 1 | V66: =RANK(V65,$F65:$CG65,0) -> 1 | Z66: =RANK(Z65,$F65:$CG65,0) -> 1 | AD66: =RANK(AD65,$F65:$CG65,0) -> 1 | AH66: =RANK(AH65,$F65:$CG65,0) -> 1 | AL66: =RANK(AL65,$F65:$CG65,0) -> 1 | AP66: =RANK(AP65,$F65:$CG65,0) -> 1 | AT66: =RANK(AT65,$F65:$CG65,0) -> 1 | AX66: =RANK(AX65,$F65:$CG65,0) -> 1 | BB66: =RANK(BB65,$F65:$CG65,0) -> 1 | BF66: =RANK(BF65,$F65:$CG65,0) -> 1 | BJ66: =RANK(BJ65,$F65:$CG65,0) -> 1 | BN66: =RANK(BN65,$F65:$CG65,0) -> 1 | BR66: =RANK(BR65,$F65:$CG65,0) -> 1 | BV66: =RANK(BV65,$F65:$CG65,0) -> 1 | BZ66: =RANK(BZ65,$F65:$CG65,0) -> 1 | CD66: =RANK(CD65,$F65:$CG65,0) -> 1
AG68: Deployment Priorities
C74: Key
...

Sheet mscr
B8: © Copyright MoreSteam.com, LLC, 2005
J10: © Copyright 2005, MoreSteam.com, LLC
J11: Altering or deleting this sheet is a violation of copyright law
